Workbook

Sheet PIN_MUX
A1: ZY PAD NAME | B1: ZY PAD TYPE | C1: FH8856v310 （内置DDR） | D1: PAD NAME | E1: Voltage(v) | F1: FUNC0 | G1: FUNC1 | H1: FUNC2 | I1: FUNC3 | J1: FUNC4 | K1: FUNC5 | L1: FUNC7 | M1: FUNC9 | N1: 摇头机 无MCU SPI电机 | O1: 摇头机 无MCU SPI+PWM电机 | P1: 摇头机 无MCU PWM电机 | Q1: HL_MAIN 主板 | R1: FH8856v310 APP板 | S1: QFN88模组
A2: RESETN | B2: PRUW08SDGZ_H_G | C2: =IFERROR( INDEX( temp_file!$B$182:$B$262,MATCH($D2,temp_file!$A$182:$A$262,0)), "#N/A" ) -> 43 | D2: RESETN | E2: 1.8V (不可配） | F2: RESETN | N2: RESETN | O2: RESETN | P2: RESETN | Q2: RESETN | R2: RESETN | S2: RESETN
A3: CLK_IN | B3: PDXOEDG_H_G | C3: =IFERROR( INDEX( temp_file!$B$182:$B$262,MATCH($D3,temp_file!$A$182:$A$262,0)), "#N/A" ) -> 41 | D3: CLK_IN | E3: 1.8V (不可配） | F3: CLK_IN | N3: CLK_IN | O3: CLK_IN | P3: CLK_IN | Q3: CLK_IN | R3: CLK_IN | S3: CLK_IN
A4: CLK | B4: PDXOEDG_H_G | C4: =IFERROR( INDEX( temp_file!$B$182:$B$262,MATCH($D4,temp_file!$A$182:$A$262,0)), "#N/A" ) -> 42 | D4: CLK | E4: 1.8V (不可配） | F4: CLK_OUT | N4: CLK_OUT | O4: CLK_OUT | P4: CLK_OUT | Q4: CLK_OUT | R4: CLK_OUT | S4: CLK_OUT
C5: =IFERROR( INDEX( temp_file!$B$182:$B$262,MATCH($D5,temp_file!$A$182:$A$262,0)), "#N/A" ) -> 77 | D5: BOOT_MODE | E5: 3.3V | F5: GPIO30 | N5: BOOT_MODE | O5: BOOT_MODE | P5: BOOT_MODE | Q5: BOOT_MODE | R5: BOOT_MODE | S5: BOOT_MODE
C6: =IFERROR( INDEX( temp_file!$B$182:$B$262,MATCH($D6,temp_file!$A$182:$A$262,0)), "#N/A" ) -> 76 | D6: BOOT_SEL1 | E6: 3.3V | F6: GPIO31 | G6: ETH_LINK_ACT_LED | N6: BOOT_SEL1 | O6: BOOT_SEL1 | P6: BOOT_SEL1 | Q6: BOOT_SEL1 | R6: BOOT_SEL1 | S6: BOOT_SEL1
C7: =IFERROR( INDEX( temp_file!$B$182:$B$262,MATCH($D7,temp_file!$A$182:$A$262,0)), "#N/A" ) -> 75 | D7: BOOT_SEL0 | E7: 3.3V | F7: GPIO32 | G7: ETH_LINK_STA_LED | H7: ETH_LINK_SPD_LED | N7: BOOT_SEL0 | O7: BOOT_SEL0 | P7: BOOT_SEL0 | Q7: BOOT_SEL0 | R7: BOOT_SEL0 | S7: BOOT_SEL0
C8: =IFERROR( INDEX( temp_file!$B$182:$B$262,MATCH($D8,temp_file!$A$182:$A$262,0)), "#N/A" ) -> 23 | D8: UART0_TX | E8: 3.3V | F8: UART0_TX | G8: GPIO33 | N8: UART0_TX | O8: UART0_TX | P8: UART0_TX | Q8: UART0_TX | R8: UART0_TX | S8: UART0_TX
C9: =IFERROR( INDEX( temp_file!$B$182:$B$262,MATCH($D9,temp_file!$A$182:$A$262,0)), "#N/A" ) -> 22 | D9: UART0_RX | E9: 3.3V | F9: UART0_RX | G9: GPIO34 | N9: UART0_RX | O9: UART0_RX | P9: UART0_RX | Q9: UART0_RX | R9: UART0_RX | S9: UART0_RX
A10: I2C0_SDA | B10: PRWHSWCDGSD_H | C10: =IFERROR( INDEX( temp_file!$B$182:$B$262,MATCH($D10,temp_file!$A$182:$A$262,0)), "#N/A" ) -> 11 | D10: I2C0_SCL | E10: 1.8V (不可配） | F10: I2C0_SCL | G10: GPIO35 | N10: I2C0_SCL | O10: I2C0_SCL | P10: I2C0_SCL | Q10: I2C0_SCL | R10: I2C0_SCL | S10: I2C0_SCL
A11: I2C0_SCL | B11: PRWHSWCDGSD_H | C11: =IFERROR( INDEX( temp_file!$B$182:$B$262,MATCH($D11,temp_file!$A$182:$A$262,0)), "#N/A" ) -> 10 | D11: I2C0_SDA | E11: 1.8V (不可配） | F11: I2C0_SDA | G11: GPIO36 | N11: I2C0_SDA | O11: I2C0_SDA | P11: I2C0_SDA | Q11: I2C0_SDA | R11: I2C0_SDA | S11: I2C0_SDA
A12: GPIO_12 | B12: PRWHSWCDGSD_H | C12: =IFERROR( INDEX( temp_file!$B$182:$B$262,MATCH($D12,temp_file!$A$182:$A$262,0)), "#N/A" ) -> 9 | D12: SENSOR_CLK | E12: 1.8V (不可配） | F12: SENSOR_CLK | G12: GPIO12 | N12: SENSOR_CLK | O12: SENSOR_CLK | P12: SENSOR_CLK | Q12: SENSOR_CLK | R12: SENSOR_CLK | S12: SENSOR_CLK
A13: GPIO_13 | B13: PRWHSWCDGSD_H | C13: =IFERROR( INDEX( temp_file!$B$182:$B$262,MATCH($D13,temp_file!$A$182:$A$262,0)), "#N/A" ) -> 8 | D13: SENSOR_RSTN | E13: 1.8V (不可配） | F13: GPIO13 | N13: SENSOR_RSTN | O13: SENSOR_RSTN | P13: SENSOR_RSTN | Q13: SENSOR_RSTN | R13: SENSOR_RSTN | S13: SENSOR_RSTN
A14: GPIO_14 | B14: PRWHSWCDGSD_H | C14: =IFERROR( INDEX( temp_file!$B$182:$B$262,MATCH($D14,temp_file!$A$182:$A$262,0)), "#N/A" ) -> 59 | D14: UART1_TX | E14: 3.3V | F14: UART1_TX | G14: GPIO39 | H14: PWM10 | I14: SD1_CLK | N14: UART1_TX | O14: UART1_TX | P14: UART1_TX | Q14: UART1_TX | R14: UART1_TX | S14: AF1_NSLEEP
A15: MAC_REF_CLK | B15: PRWHSWCDGSD_H | C15: =IFERROR( INDEX( temp_file!$B$182:$B$262,MATCH($D15,temp_file!$A$182:$A$262,0)), "#N/A" ) -> 58 | D15: UART1_RX | E15: 3.3V | F15: UART1_RX | G15: GPIO40 | H15: PWM11 | I15: SD1_CD | N15: UART1_RX | O15: UART1_RX | P15: UART1_RX | Q15: UART1_RX | R15: UART1_RX | S15: AF2_NSLEEP
A16: MAC_RMII_CLK | B16: PRWHSWCDGSD_H | C16: =IFERROR( INDEX( temp_file!$B$182:$B$262,MATCH($D16,temp_file!$A$182:$A$262,0)), "#N/A" ) -> 55 | D16: I2C1_SCL | E16: 3.3V | F16: I2C1_SCL | G16: GPIO37 | H16: PWM2 | I16: SD1_CMD_RSP | J16: STM_H_0 | K16: SSI1_CLK | N16: 电机 SSI1_CLK | O16: 水平电机 SSI1_CLK | P16: 水平电机 PWM2 | Q16: PWM2 | R16: 水平电机 PWM2 | S16: 电机 PWM2
A17: MAC_RXD_0 | B17: PRWHSWCDGSD_H | C17: =IFERROR( INDEX( temp_file!$B$182:$B$262,MATCH($D17,temp_file!$A$182:$A$262,0)), "#N/A" ) -> 54 | D17: I2C1_SDA | E17: 3.3V | F17: I2C1_SDA | G17: GPIO38 | H17: PWM3 | I17: SD1_DATA_0 | J17: STM_H_1 | K17: SSI1_CSN_0 | N17: 电机 SSI1_CSN_0 | O17: 水平电机 SSI1_CSN_0 | P17: 水平电机 PWM3 | Q17: PWM3 | R17: 水平电机 PWM3 | S17: 电机 PWM3
A18: MAC_RXD_1 | B18: PRWHSWCDGSD_H | C18: =IFERROR( INDEX( temp_file!$B$182:$B$262,MATCH($D18,temp_file!$A$182:$A$262,0)), "#N/A" ) -> 57 | D18: UART2_TX | E18: 3.3V | F18: UART2_TX | G18: GPIO41 | H18: PWM4 | I18: SD1_DATA_1 | J18: STM_H_2 | K18: SSI1_TXD | N18: 电机 SSI1_TXD | O18: 水平电机 SSI1_TXD | P18: 水平电机 PWM4 | Q18: PWM4 | R18: 水平电机 PWM4 | S18: 电机 PWM4/UART2_TX
A19: MAC_RXDV | B19: PRWHSWCDGSD_H | C19: =IFERROR( INDEX( temp_file!$B$182:$B$262,MATCH($D19,temp_file!$A$182:$A$262,0)), "#N/A" ) -> 56 | D19: UART2_RX | E19: 3.3V | F19: UART2_RX | G19: GPIO42 | H19: PWM5 | I19: SD1_DATA_2 | J19: STM_H_3 | K19: SSI1_RXD | N19: 电机 SSI1_RXD | O19: 水平电机 SSI1_RXD | P19: 水平电机 PWM5 | Q19: PWM5 | R19: 水平电机 PWM5 | S19: 电机 PWM5/UART2_RX
A20: MAC_TXD_0 | B20: PRWHSWCDGSD_H | C20: =IFERROR( INDEX( temp_file!$B$182:$B$262,MATCH($D20,temp_file!$A$182:$A$262,0)), "#N/A" ) -> 60 | D20: USB_PWREN | E20: 3.3V | F20: USB_PWREN | G20: GPIO47 | I20: SD1_DATA_3 | N20: USB_PWREN | O20: USB_PWREN | P20: USB_PWREN | Q20: USB_PWREN | R20: USB_PWREN | S20: USB_PWREN(WIFI&4G RESET)
A21: MAC_TXD_1 | B21: PRWHSWCDGSD_H | C21: =IFERROR( INDEX( temp_file!$B$182:$B$262,MATCH($D21,temp_file!$A$182:$A$262,0)), "#N/A" ) -> 25 | D21: PWM0 | E21: 3.3V | F21: PWM0 | G21: GPIO43 | H21: I2C2_SCL | I21: UART2_TX | N21: VD_FZ | O21: VD_FZ | P21: ICR_ON | Q21: ICR_ON/WIFI_INT/AK7755复位 | R21: ICR_ON | S21: W_LIGHT（白光PWM）
A22: MAC_TXEN | B22: PRWHSWCDGSD_H | C22: =IFERROR( INDEX( temp_file!$B$182:$B$262,MATCH($D22,temp_file!$A$182:$A$262,0)), "#N/A" ) -> 24 | D22: PWM1 | E22: 3.3V | F22: PWM1 | G22: GPIO44 | H22: I2C2_SDA | I22: UART2_RX | N22: 出厂复位 | O22: 出厂复位 | P22: 出厂复位 | Q22: 出厂复位/WL_REG_ON | R22: 出厂复位 | S22: IR_LIGHT (红外PWM)
A23: GPIO_9 | B23: PRWHSWCDGSD_H | C23: =IFERROR( INDEX( temp_file!$B$182:$B$262,MATCH($D23,temp_file!$A$182:$A$262,0)), "#N/A" ) -> 47 | D23: GPIO0 | E23: 3.3V | F23: ARM_JTAG_TRSTN | G23: GPIO0 | H23: ACW_I2S_DO(Slave) | I23: DW_I2S_DO(master) | J23: SSI1_CLK | K23: SSI2_CLK | L23: PWM6 | M23: STM_V_0 | N23: ACW_I2S_DO(Slave) | O23: 垂直电机 PWM6 | P23: 垂直电机 PWM6 | Q23: PWM6 | R23: 垂直电机 PWM6/ARM_JTAG_TRSTN | S23: MOTO_C(电机切换)
A24: GPIO_10 | B24: PRWHSWCDGSD_H | C24: =IFERROR( INDEX( temp_file!$B$182:$B$262,MATCH($D24,temp_file!$A$182:$A$262,0)), "#N/A" ) -> 48 | D24: GPIO1 | E24: 3.3V | F24: ARM_JTAG_TDO | G24: GPIO1 | H24: ACW_I2S_DI(Slave) | I24: DW_I2S_DI(master) | J24: SSI1_CSN_0 | K24: SSI2_CSN_0 | L24: PWM7 | M24: STM_V_1 | N24: ACW_I2S_DI(Slave) | O24: 垂直电机 PWM7 | P24: 垂直电机 PWM7 | Q24: PWM7 | R24: 垂直电机 PWM7/ARM_JTAG_TDO
A25: GPIO_11 | B25: PRWHSWCDGSD_H | C25: =IFERROR( INDEX( temp_file!$B$182:$B$262,MATCH($D25,temp_file!$A$182:$A$262,0)), "#N/A" ) -> 49 | D25: GPIO2 | E25: 3.3V | F25: ARM_JTAG_TDI | G25: GPIO2 | H25: ACW_I2S_CLK(Slave) | I25: DW_I2S_CLK(master) | J25: SSI1_TXD | K25: SSI2_TXD | L25: PWM8 | M25: STM_V_2 | N25: ACW_I2S_CLK(Slave) | O25: 垂直电机 PWM8 | P25: 垂直电机 PWM8 | Q25: PWM8 | R25: 垂直电机 PWM8/ARM_JTAG_TDI
A26: SSI0_CLK | B26: PRWHSWCDGSD_H | C26: =IFERROR( INDEX( temp_file!$B$182:$B$262,MATCH($D26,temp_file!$A$182:$A$262,0)), "#N/A" ) -> 50 | D26: GPIO3 | E26: 3.3V | F26: ARM_JTAG_TCK | G26: GPIO3 | H26: ACW_I2S_WS(Slave) | I26: DW_I2S_WS(master) | J26: SSI1_RXD | K26: SSI2_RXD | L26: PWM9 | M26: STM_V_3 | N26: ACW_I2S_WS(Slave) | O26: 垂直电机 PWM9 | P26: 垂直电机 PWM9 | Q26: PWM9 | R26: 垂直电机 PWM9ARM_JTAG_TCK
A27: SSI0_CSN_0 | B27: PRWHSWCDGSD_H | C27: =IFERROR( INDEX( temp_file!$B$182:$B$262,MATCH($D27,temp_file!$A$182:$A$262,0)), "#N/A" ) -> 51 | D27: GPIO4 | E27: 3.3V | F27: ARM_JTAG_TMS | G27: GPIO4 | H27: AC_MCLK | I27: USB_PWREN | J27: SD1_CD | N27: AC_MCLK | O27: 电机驱动 reset | P27: ICR_OFF | Q27: AC_MCLK/ICR_OFF | R27: ICR_OFF / ARM_JTAG_TMS
A28: SSI0_CSN_1 | B28: PRWHSWCDGSD_H | C28: =IFERROR( INDEX( temp_file!$B$182:$B$262,MATCH($D28,temp_file!$A$182:$A$262,0)), "#N/A" ) -> 26 | D28: SSI0_CLK | E28: 3.3V | F28: SSI0_CLK | G28: GPIO5 | J28: SD1_CLK（emmc） | N28: SSI0_CLK | O28: SSI0_CLK | P28: SSI0_CLK | Q28: SSI0_CLK | R28: SSI0_CLK | S28: SSI0_CLK
A29: SSI0_TXD | B29: PRWHSWCDGSD_H | C29: =IFERROR( INDEX( temp_file!$B$182:$B$262,MATCH($D29,temp_file!$A$182:$A$262,0)), "#N/A" ) -> 27 | D29: SSI0_CSN_0 | E29: 3.3V | F29: SSI0_CSN_0 | G29: GPIO6 | J29: SD1_CMD_RSP（emmc） | N29: SSI0_CSN_0 | O29: SSI0_CSN_0 | P29: SSI0_CSN_0 | Q29: SSI0_CSN_0 | R29: SSI0_CSN_0 | S29: SSI0_CSN_0
A30: SSI0_RXD | B30: PRWHSWCDGSD_H | C30: =IFERROR( INDEX( temp_file!$B$182:$B$262,MATCH($D30,temp_file!$A$182:$A$262,0)), "#N/A" ) -> 28 | D30: SSI0_TXD | E30: 3.3V | F30: SSI0_TXD(SSI0_D0) | G30: GPIO7 | J30: SD1_DATA_0（emmc） | N30: SSI0_TXD(SSI0_D0) | O30: SSI0_TXD(SSI0_D0) | P30: SSI0_TXD(SSI0_D0) | Q30: SSI0_TXD(SSI0_D0) | R30: SSI0_TXD(SSI0_D0) | S30: SSI0_TXD(SSI0_D0)
A31: SSI0_D_2 | B31: PRWHSWCDGSD_H | C31: =IFERROR( INDEX( temp_file!$B$182:$B$262,MATCH($D31,temp_file!$A$182:$A$262,0)), "#N/A" ) -> 29 | D31: SSI0_RXD | E31: 3.3V | F31: SSI0_RXD(SSI0_D1) | G31: GPIO8 | J31: SD1_DATA_1（emmc） | N31: SSI0_RXD(SSI0_D1) | O31: SSI0_RXD(SSI0_D1) | P31: SSI0_RXD(SSI0_D1) | Q31: SSI0_RXD(SSI0_D1) | R31: SSI0_RXD(SSI0_D1) | S31: SSI0_RXD(SSI0_D1)
A32: SSI0_D_3 | B32: PRWHSWCDGSD_H | C32: =IFERROR( INDEX( temp_file!$B$182:$B$262,MATCH($D32,temp_file!$A$182:$A$262,0)), "#N/A" ) -> 30 | D32: SSI0_D2 | E32: 3.3V | F32: SSI0_D2 | G32: GPIO9 | H32: UART1_TX | I32: I2C1_SCL | J32: SD1_DATA_2（emmc） | N32: I2C1_SCL | O32: LED_RED | P32: LED_RED | Q32: SSI0_D2 | R32: SSI0_D2
A33: UART_RX | B33: PRWHSWCDGSD_H | C33: =IFERROR( INDEX( temp_file!$B$182:$B$262,MATCH($D33,temp_file!$A$182:$A$262,0)), "#N/A" ) -> 31 | D33: SSI0_D3 | E33: 3.3V | F33: SSI0_D3 | G33: GPIO10 | H33: UART1_RX | I33: I2C1_SDA | J33: SD1_DATA_3（emmc） | N33: I2C1_SDA | O33: LED_BLUE | P33: LED_BLUE | Q33: SSI0_D3 | R33: SSI0_D3 | S33: H_LIGHT
A34: GPIO_22 | B34: PRWHSWCDGSD_H | C34: =IFERROR( INDEX( temp_file!$B$182:$B$262,MATCH($D34,temp_file!$A$182:$A$262,0)), "#N/A" ) -> 88 | D34: SD0_CD | E34: 3.3V | F34: SD0_CD | G34: GPIO17 | I34: ARC_JTAG_TRSTN | J34: PAE_JTAG_TRSTN | N34: SD0_CD | O34: SD0_CD | P34: SD0_CD | Q34: SD0_CD | R34: SD0_CD | S34: SD0_CD
A35: GPIO_23 | B35: PRWHSWCDGSD_H | C35: =IFERROR( INDEX( temp_file!$B$182:$B$262,MATCH($D35,temp_file!$A$182:$A$262,0)), "#N/A" ) -> 87 | D35: SD0_CLK | E35: 3.3V | F35: SD0_CLK | G35: GPIO18 | H35: SSI1_CLK（标准复用） | I35: ARC_JTAG_TDO | J35: PAE_JTAG_TDO | N35: SD0_CLK | O35: SD0_CLK | P35: SD0_CLK | Q35: SD0_CLK | R35: SD0_CLK | S35: SD0_CLK
A36: GPIO_24 | B36: PRWHSWCDGSD_H | C36: =IFERROR( INDEX( temp_file!$B$182:$B$262,MATCH($D36,temp_file!$A$182:$A$262,0)), "#N/A" ) -> 86 | D36: SD0_CMD_RSP | E36: 3.3V | F36: SD0_CMD_RSP | G36: GPIO19 | H36: SSI1_TXD（标准复用） | I36: ARC_JTAG_TDI | J36: PAE_JTAG_TDI | N36: SD0_CMD_RSP | O36: SD0_CMD_RSP | P36: SD0_CMD_RSP | Q36: SD0_CMD_RSP | R36: SD0_CMD_RSP | S36: SD0_CMD_RSP
A37: GPIO_25 | B37: PRWHSWCDGSD_H | C37: =IFERROR( INDEX( temp_file!$B$182:$B$262,MATCH($D37,temp_file!$A$182:$A$262,0)), "#N/A" ) -> 85 | D37: SD0_DATA_0 | E37: 3.3V | F37: SD0_DATA_0 | G37: GPIO20 | H37: SSI1_RXD（标准复用） | I37: ARC_JTAG_TCK | J37: PAE_JTAG_TCK | N37: SD0_DATA_0 | O37: SD0_DATA_0 | P37: SD0_DATA_0 | Q37: SD0_DATA_0 | R37: SD0_DATA_0 | S37: SD0_DATA_0
A38: GPIO_26 | B38: PRWHSWCDGSD_H | C38: =IFERROR( INDEX( temp_file!$B$182:$B$262,MATCH($D38,temp_file!$A$182:$A$262,0)), "#N/A" ) -> 84 | D38: SD0_DATA_1 | E38: 3.3V | F38: SD0_DATA_1 | G38: GPIO21 | H38: SSI1_CSN_0（自定义复用） | I38: ARC_JTAG_TMS | J38: PAE_JTAG_TMS | N38: SD0_DATA_1 | O38: SD0_DATA_1 | P38: SD0_DATA_1 | Q38: SD0_DATA_1 | R38: SD0_DATA_1 | S38: 出厂复位
A39: GPIO_27 | B39: PRWHSWCDGSD_H | C39: =IFERROR( INDEX( temp_file!$B$182:$B$262,MATCH($D39,temp_file!$A$182:$A$262,0)), "#N/A" ) -> 83 | D39: SD0_DATA_2 | E39: 3.3V | F39: SD0_DATA_2 | G39: GPIO22 | I39: UART2_TX | J39: I2C2_SCL | N39: SD0_DATA_2 | O39: SD0_DATA_2 | P39: SD0_DATA_2 | Q39: SD0_DATA_2 | R39: SD0_DATA_2 | S39: ICR_OFF
A40: GPIO_28 | B40: PRWHSWCDGSD_H | C40: =IFERROR( INDEX( temp_file!$B$182:$B$262,MATCH($D40,temp_file!$A$182:$A$262,0)), "#N/A" ) -> 82 | D40: SD0_DATA_3 | E40: 3.3V | F40: SD0_DATA_3 | G40: GPIO23 | H40: SSI1_CSN_1（标准复用） | I40: UART2_RX | J40: I2C2_SDA | N40: SD0_DATA_3 | O40: SD0_DATA_3 | P40: SD0_DATA_3 | Q40: SD0_DATA_3 | R40: SD0_DATA_3 | S40: ICR_ON
...

Sheet 管脚分布
D2: SD0_CD | E2: SD0_CLK | F2: SD0_CMD_RSP | G2: SD0_DATA_0 | H2: SD0_DATA_1 | I2: SD0_DATA_2 | J2: SD0_DATA_3 | K2: GPIO29 | L2: GPIO28 | M2: VDDK | N2: VDDIO_18OD33 | O2: BOOT_MODE | P2: BOOT_SEL1 | Q2: BOOT_SEL0 | R2: VDDK | S2: VDDIO_18/VDDA18_EPHY | T2: EPHY_RTX | U2: VDDA33_EPHY | V2: EPHY_TXP | W2: EPHY_TXN | X2: EPHY_RXP | Y2: EPHY_RXN
D3: 88 | E3: 87 | F3: 86 | G3: 85 | H3: 84 | I3: 83 | J3: 82 | K3: 81 | L3: 80 | M3: 79 | N3: 78 | O3: 77 | P3: 76 | Q3: 75 | R3: 74 | S3: 73 | T3: 72 | U3: 71 | V3: 70 | W3: 69 | X3: 68 | Y3: 67
B4: DN0_MIPI | C4: 1 | D4: FH8856V310 | Z4: 66 | AA4: USB_REXT | AD4: DEVICE 1.8/3.3V
B5: DP0_MIPI | C5: 2 | Z5: 65 | AA5: USB_DM | AD5: PLL 1.8V
B6: DP1_MIPI | C6: 3 | Z6: 64 | AA6: USB_DP | AD6: Dig 1.8V
B7: DN1_MIPI | C7: 4 | Z7: 63 | AA7: VDDA33_USB | AD7: MIPI 1.8V
B8: CKN_MIPI | C8: 5 | Z8: 62 | AA8: USB_VBUS | AD8: USB
B9: CKP_MIPI | C9: 6 | Z9: 61 | AA9: VDDIO_18/VDDA18_USB | AD9: RTC
B10: REXT_MIPI | C10: 7 | Z10: 60 | AA10: USB_PWREN | AD10: DDR
B11: SENSOR_RSTN | C11: 8 | Z11: 59 | AA11: UART1_TX | AD11: ANA 1.8V
B12: SENSOR_CLK | C12: 9 | Z12: 58 | AA12: UART1_RX | AD12: EPHY
B13: I2C0_SDA | C13: 10 | Z13: 57 | AA13: UART2_TX
B14: I2C0_SCL | C14: 11 | Z14: 56 | AA14: UART2_RX | AD14: 外接电阻
B15: XAIN0_SADC | C15: 12 | Z15: 55 | AA15: I2C1_SCL
B16: XAIN1_SADC | C16: 13 | Z16: 54 | AA16: I2C1_SDA
B17: VDDA18_AC/MIPI/SADC | C17: 14 | Z17: 53 | AA17: VDDK
B18: LOUT_AC | C18: 15 | Z18: 52 | AA18: VDDIO_18OD33
B19: VMID_AC | C19: 16 | Z19: 51 | AA19: GPIO4
B20: MICINP_AC | C20: 17 | Z20: 50 | AA20: GPIO3
B21: MICBIAS_AC | C21: 18 | Z21: 49 | AA21: GPIO2
B22: VDDK | C22: 19 | Z22: 48 | AA22: GPIO1 | AE22: FH8856v310内置DDR3L颗粒电源 | AF22: 1.35V
B23: VDDIO_18 | C23: 20 | Z23: 47 | AA23: GPIO0
B24: VDDIO_18OD33 | C24: 21 | Z24: 46 | AA24: XOUT_RTC
B25: UART0_RX | C25: 22 | Z25: 45 | AA25: XIN_RTC
D26: 23 | E26: 24 | F26: 25 | G26: 26 | H26: 27 | I26: 28 | J26: 29 | K26: 30 | L26: 31 | M26: 32 | N26: 33 | O26: 34 | P26: 35 | Q26: 36 | R26: 37 | S26: 38 | T26: 39 | U26: 40 | V26: 41 | W26: 42 | X26: 43 | Y26: 44
D27: UART0_TX | E27: PWM1 | F27: PWM0 | G27: SSIO_CLK | H27: SSIO_CSN_0 | I27: SSIO_TXD | J27: SSIO_RXD | K27: SSIO_D2 | L27: SSIO_D3 | M27: VDDK | N27: VDDIO_DDR_135 | O27: DDR_ZQ | P27: DDR_CAL | Q27: VDDIO_DDR_135 | R27: GNDA_PLL | S27: VDDA09_PLL | T27: VDDA18_PLL | U27: VDDK | V27: CLK_IN | W27: CLK | X27: RESETN | Y27: VDDA_RTC

Sheet IO_STATUS
A1: FH8856v310 Pin_num | B1: PAD Name | C1: Default Function | D1: Default MFS [27:24] | E1: IO电源已上电，CORE电源未上电 | G1: IO/CORE电源已上电，复位撤销之前 | I1: IO电源和CORE都已上电，复位撤销之后，ROM开始执行到结束期间。 | K1: ScanPU | L1: ScanPD
E2: 电平状态 | F2: I/O类型 | G2: 电平状态 | H2: I/O类型 | I2: 电平状态 | J2: I/O类型 | K2: 电平状态 | L2: 电平状态
A3: =PIN_MUX!C2 -> 43 | B3: =PIN_MUX!D2 -> RESETN | C3: =[1]PIN_MUX!K6 -> RESETN | D3: N/A | E3: HiZ | F3: NA | G3: PU | H3: I | I3: PU | J3: I | K3: PU=1 | L3: PD=0
A4: =PIN_MUX!C3 -> 41 | B4: =PIN_MUX!D3 -> CLK_IN | C4: =[1]PIN_MUX!K8 -> CLK_IN | D4: N/A | E4: HiZ | F4: NA | G4: HiZ | H4: I | I4: 0/1 | J4: I | K4: - | L4: -
A5: =PIN_MUX!C4 -> 42 | B5: =PIN_MUX!D4 -> CLK | C5: =[1]PIN_MUX!K9 -> CLK_OUT | D5: N/A | E5: HiZ | F5: NA | G5: X | H5: O | I5: 0/1 | J5: O | K5: - | L5: -
A6: =PIN_MUX!C5 -> 77 | B6: =PIN_MUX!D5 -> BOOT_MODE | C6: =[1]PIN_MUX!K10 -> GPIO30 | D6: Func0 | E6: HiZ | F6: NA | G6: PU | H6: I | I6: PU | J6: I | K6: PU=0 | L6: PD=0
A7: =PIN_MUX!C6 -> 76 | B7: =PIN_MUX!D6 -> BOOT_SEL1 | C7: =[1]PIN_MUX!K11 -> GPIO31 | D7: Func0 | E7: HiZ | F7: NA | G7: PU | H7: I | I7: PU | J7: I | K7: PU=0 | L7: PD=0
A8: =PIN_MUX!C7 -> 75 | B8: =PIN_MUX!D7 -> BOOT_SEL0 | C8: =[1]PIN_MUX!K12 -> GPIO32 | D8: Func0 | E8: HiZ | F8: NA | G8: PU | H8: I | I8: PU | J8: I | K8: PU=0 | L8: PD=0
A9: =PIN_MUX!C8 -> 23 | B9: =PIN_MUX!D8 -> UART0_TX | C9: =[1]PIN_MUX!K13 -> UART0_TX | D9: Func0 | E9: HiZ | F9: NA | G9: H | H9: O | I9: 0/1 | J9: O | K9: PU=0 | L9: PD=0
A10: =PIN_MUX!C9 -> 22 | B10: =PIN_MUX!D9 -> UART0_RX | C10: =[1]PIN_MUX!K14 -> UART0_RX | D10: Func0 | E10: HiZ | F10: NA | G10: PU | H10: I | I10: 0/1 | J10: I | K10: PU=0 | L10: PD=0 | M10: autoload: 常0 安全模式：会翻转
A11: =PIN_MUX!C10 -> 11 | B11: =PIN_MUX!D10 -> I2C0_SCL | C11: =[1]PIN_MUX!L15 -> GPIO35 | D11: Func1 | E11: HiZ | F11: NA | G11: PU | H11: I | I11: PU | J11: I | K11: PU=0 | L11: PD=0
A12: =PIN_MUX!C11 -> 10 | B12: =PIN_MUX!D11 -> I2C0_SDA | C12: =[1]PIN_MUX!L16 -> GPIO36 | D12: Func1 | E12: HiZ | F12: NA | G12: PU | H12: I | I12: PU | J12: I | K12: PU=0 | L12: PD=0
A13: =PIN_MUX!C12 -> 9 | B13: =PIN_MUX!D12 -> SENSOR_CLK | C13: =[1]PIN_MUX!L17 -> GPIO12 | D13: Func1 | E13: HiZ | F13: NA | G13: HiZ | H13: I | I13: HiZ | J13: I | K13: PU=0 | L13: PD=0
A14: =PIN_MUX!C13 -> 8 | B14: =PIN_MUX!D13 -> SENSOR_RSTN | C14: =[1]PIN_MUX!K18 -> GPIO13 | D14: Func0 | E14: HiZ | F14: NA | G14: HiZ | H14: I | I14: HiZ | J14: I | K14: PU=0 | L14: PD=0
A15: =PIN_MUX!C14 -> 59 | B15: =PIN_MUX!D14 -> UART1_TX | C15: =[1]PIN_MUX!L20 -> GPIO39 | D15: Func1 | E15: HiZ | F15: NA | G15: HiZ | H15: I | I15: HiZ | J15: I | K15: PU=0 | L15: PD=0
A16: =PIN_MUX!C15 -> 58 | B16: =PIN_MUX!D15 -> UART1_RX | C16: =[1]PIN_MUX!L21 -> GPIO40 | D16: Func1 | E16: HiZ | F16: NA | G16: HiZ | H16: I | I16: HiZ | J16: I | K16: PU=0 | L16: PD=0
A17: =PIN_MUX!C16 -> 55 | B17: =PIN_MUX!D16 -> I2C1_SCL | C17: =[1]PIN_MUX!L22 -> GPIO37 | D17: Func1 | E17: HiZ | F17: NA | G17: HiZ | H17: I | I17: HiZ | J17: I | K17: PU=0 | L17: PD=0
A18: =PIN_MUX!C17 -> 54 | B18: =PIN_MUX!D17 -> I2C1_SDA | C18: =[1]PIN_MUX!L23 -> GPIO38 | D18: Func1 | E18: HiZ | F18: NA | G18: HiZ | H18: I | I18: HiZ | J18: I | K18: PU=0 | L18: PD=0
A19: =PIN_MUX!C18 -> 57 | B19: =PIN_MUX!D18 -> UART2_TX | C19: =[1]PIN_MUX!L24 -> GPIO41 | D19: Func1 | E19: HiZ | F19: NA | G19: HiZ | H19: I | I19: HiZ | J19: I | K19: PU=0 | L19: PD=0
A20: =PIN_MUX!C19 -> 56 | B20: =PIN_MUX!D19 -> UART2_RX | C20: =[1]PIN_MUX!L25 -> GPIO42 | D20: Func1 | E20: HiZ | F20: NA | G20: HiZ | H20: I | I20: HiZ | J20: I | K20: PU=0 | L20: PD=0
A21: =PIN_MUX!C20 -> 60 | B21: =PIN_MUX!D20 -> USB_PWREN | C21: =[1]PIN_MUX!L26 -> GPIO47 | D21: Func1 | E21: HiZ | F21: NA | G21: HiZ | H21: I | I21: HiZ | J21: I | K21: PU=0 | L21: PD=0
A22: =PIN_MUX!C21 -> 25 | B22: =PIN_MUX!D21 -> PWM0 | C22: =[1]PIN_MUX!L27 -> GPIO43 | D22: Func1 | E22: HiZ | F22: NA | G22: HiZ | H22: I | I22: HiZ | J22: I | K22: PU=0 | L22: PD=0
A23: =PIN_MUX!C22 -> 24 | B23: =PIN_MUX!D22 -> PWM1 | C23: =[1]PIN_MUX!L28 -> GPIO44 | D23: Func1 | E23: HiZ | F23: NA | G23: HiZ | H23: I | I23: HiZ | J23: I | K23: PU=0 | L23: PD=0
A24: =PIN_MUX!C23 -> 47 | B24: =PIN_MUX!D23 -> GPIO0 | C24: =[1]PIN_MUX!K48 -> ARM_JTAG_TRSTN | D24: Func0 | E24: HiZ | F24: NA | G24: HiZ | H24: I | I24: HiZ | J24: I | K24: PU=0 | L24: PD=0
A25: =PIN_MUX!C24 -> 48 | B25: =PIN_MUX!D24 -> GPIO1 | C25: =[1]PIN_MUX!K49 -> ARM_JTAG_TDO | D25: Func0 | E25: HiZ | F25: NA | G25: HiZ | H25: I | I25: HiZ | J25: I | K25: PU=0 | L25: PD=0 | M25: ROM期间JTAG不启动，因此始终为输入
A26: =PIN_MUX!C25 -> 49 | B26: =PIN_MUX!D25 -> GPIO2 | C26: =[1]PIN_MUX!K50 -> ARM_JTAG_TDI | D26: Func0 | E26: HiZ | F26: NA | G26: HiZ | H26: I | I26: HiZ | J26: I | K26: PU=0 | L26: PD=0
A27: =PIN_MUX!C26 -> 50 | B27: =PIN_MUX!D26 -> GPIO3 | C27: =[1]PIN_MUX!K51 -> ARM_JTAG_TCK | D27: Func0 | E27: HiZ | F27: NA | G27: HiZ | H27: I | I27: HiZ | J27: I | K27: PU=0 | L27: PD=0
A28: =PIN_MUX!C27 -> 51 | B28: =PIN_MUX!D27 -> GPIO4 | C28: =[1]PIN_MUX!K52 -> ARM_JTAG_TMS | D28: Func0 | E28: HiZ | F28: NA | G28: HiZ | H28: I | I28: HiZ | J28: I | K28: PU=0 | L28: PD=0
A29: =PIN_MUX!C28 -> 26 | B29: =PIN_MUX!D28 -> SSI0_CLK | C29: =[1]PIN_MUX!K53 -> SSI0_CLK | D29: Func0 | E29: HiZ | F29: NA | G29: L | H29: O | I29: 0/1 | J29: O | K29: PU=0 | L29: PD=0
A30: =PIN_MUX!C29 -> 27 | B30: =PIN_MUX!D29 -> SSI0_CSN_0 | C30: =[1]PIN_MUX!K54 -> SSI0_CSN_0 | D30: Func0 | E30: HiZ | F30: NA | G30: H | H30: O | I30: 0/1 | J30: I/O | K30: PU=0 | L30: PD=0 | M30: flash：输出 emmc：也是输出，但是会短暂切为输入
A31: =PIN_MUX!C30 -> 28 | B31: =PIN_MUX!D30 -> SSI0_TXD | C31: =[1]PIN_MUX!K55 -> SSI0_TXD(SSI0_D0) | D31: Func0 | E31: HiZ | F31: NA | G31: HiZ | H31: I | I31: 0/1 | J31: I/O | K31: PU=0 | L31: PD=0 | M31: flash：默认输入，有数据时变成输出 emmc：仅输出
A32: =PIN_MUX!C31 -> 29 | B32: =PIN_MUX!D31 -> SSI0_RXD | C32: =[1]PIN_MUX!K56 -> SSI0_RXD(SSI0_D1) | D32: Func0 | E32: HiZ | F32: NA | G32: HiZ | H32: I | I32: PU | J32: I | K32: PU=0 | L32: PD=0
A33: =PIN_MUX!C32 -> 30 | B33: =PIN_MUX!D32 -> SSI0_D2 | C33: =[1]PIN_MUX!K57 -> SSI0_D2 | D33: Func0 | E33: HiZ | F33: NA | G33: HiZ | H33: I | I33: HiZ | J33: I | K33: PU=0 | L33: PD=0
A34: =PIN_MUX!C33 -> 31 | B34: =PIN_MUX!D33 -> SSI0_D3 | C34: =[1]PIN_MUX!K58 -> SSI0_D3 | D34: Func0 | E34: HiZ | F34: NA | G34: HiZ | H34: I | I34: HiZ | J34: I | K34: PU=0 | L34: PD=0
A35: =PIN_MUX!C34 -> 88 | B35: =PIN_MUX!D34 -> SD0_CD | C35: =[1]PIN_MUX!K63 -> SD0_CD | D35: Func0 | E35: HiZ | F35: NA | G35: HiZ | H35: I | I35: HiZ | J35: I | K35: PU=0 | L35: PD=0
A36: =PIN_MUX!C35 -> 87 | B36: =PIN_MUX!D35 -> SD0_CLK | C36: =[1]PIN_MUX!K64 -> SD0_CLK | D36: Func0 | E36: HiZ | F36: NA | G36: L | H36: O | I36: 0/1 | J36: O | K36: PU=0 | L36: PD=0
A37: =PIN_MUX!C36 -> 86 | B37: =PIN_MUX!D36 -> SD0_CMD_RSP | C37: =[1]PIN_MUX!K65 -> SD0_CMD_RSP | D37: Func0 | E37: HiZ | F37: NA | G37: HiZ | H37: I | I37: 0/1 | J37: I/O | K37: PU=0 | L37: PD=0 | M37: 默认输入，emmc时仅输出
A38: =PIN_MUX!C37 -> 85 | B38: =PIN_MUX!D37 -> SD0_DATA_0 | C38: =[1]PIN_MUX!K66 -> SD0_DATA_0 | D38: Func0 | E38: HiZ | F38: NA | G38: HiZ | H38: I | I38: HiZ | J38: I | K38: PU=0 | L38: PD=0
A39: =PIN_MUX!C38 -> 84 | B39: =PIN_MUX!D38 -> SD0_DATA_1 | C39: =[1]PIN_MUX!K67 -> SD0_DATA_1 | D39: Func0 | E39: HiZ | F39: NA | G39: HiZ | H39: I | I39: HiZ | J39: I | K39: PU=0 | L39: PD=0
A40: =PIN_MUX!C39 -> 83 | B40: =PIN_MUX!D39 -> SD0_DATA_2 | C40: =[1]PIN_MUX!K68 -> SD0_DATA_2 | D40: Func0 | E40: HiZ | F40: NA | G40: HiZ | H40: I | I40: HiZ | J40: I | K40: PU=0 | L40: PD=0
...

Sheet temp_file
A1: VSS | B1: W13
A2: DDR_ODT | B2: A2
A3: DDR_A14 | B3: A3
A4: nan | B4: Y18
A5: DDR_A1 | B5: A5
A6: DDR_BA1 | B6: A6
A7: DDR_CKE | B7: A8
A8: DDR_CLK_N | B8: A9
A9: DDR_DQ1 | B9: A11
A10: DDR_DQ4 | B10: A13
A11: DDR_DQS1_P | B11: A15
A12: DDR_DQS0_N | B12: A16
... A180: CKP_MIPI | B180: Y17
A182: DN0_MIPI | B182: 1
A183: DP0_MIPI | B183: 2
A184: DP1_MIPI | B184: 3
A185: DN1_MIPI | B185: 4
A186: CKN_MIPI | B186: 5
A187: CKP_MIPI | B187: 6
A188: REXT_MIPI | B188: 7
A189: SENSOR_RSTN | B189: 8
A190: SENSOR_CLK | B190: 9
A191: I2C0_SDA | B191: 10
A192: I2C0_SCL | B192: 11
A193: XAIN0_SADC | B193: 12
... A261: VDDA_RTC | B261: 44

Sheet 管脚列表QFN88
B2: QFN88
B3: Pin# | C3: Pin_Name | D3: Remark
B4: 1 | C4: DN0_MIPI | D4: MIPI接口差分数据0负极。
B5: 2 | C5: DP0_MIPI | D5: MIPI接口差分数据0正极。
B6: 3 | C6: DP1_MIPI | D6: MIPI接口差分数据1正极。
B7: 4 | C7: DN1_MIPI | D7: MIPI接口差分数据1负极。
B8: 5 | C8: CKN_MIPI | D8: MIPI接口差分时钟负极。
B9: 6 | C9: CKP_MIPI | D9: MIPI接口差分时钟正极。
B10: 7 | C10: REXT_MIPI | D10: 外接4.02KΩ电阻(±1%)
B11: 8 | C11: SENSOR_RSTN | D11: 1.8V Image Sensor复位信号。
B12: 9 | C12: SENSOR_CLK | D12: 1.8V Image Sensor工作时钟。
B13: 10 | C13: I2C0_SDA | D13: 1.8V I2C总线0数据/地址。
B14: 11 | C14: I2C0_SCL | D14: 1.8V I2C总线0时钟。
B15: 12 | C15: XAIN0_SADC | D15: 1.8V SADC通道0。
... B91: 88 | C91: SD0_CD | D91: 3.3V SDIO0电源使能控制信号，默认低电平有效，极性可以配置。

Sheet 更新记录
A1: 日期 | B1: 版本 | D1: 更新记录：
A2: 45012 | B2: 1 | D2: 新建pinout。
