Workbook

Sheet PIN_MUX
A1: ZY PAD NAME | B1: ZY PAD TYPE | C1: FH8858v310 （外置DDR） | D1: PAD NAME | E1: Voltage(v) | F1: FUNC0 | G1: FUNC1 | H1: FUNC2 | I1: FUNC3 | J1: FUNC4 | K1: FUNC5 | L1: FUNC7 | M1: FUNC9 | N1: 摇头机 无MCU SPI电机 | O1: 摇头机 无MCU SPI+PWM电机 | P1: 摇头机 无MCU PWM电机 | Q1: HL_MAIN 主板 | R1: FH8858v310 APP板 | S1: BGA模组
A2: RESETN | B2: PRUW08SDGZ_H_G | C2: =IFERROR( INDEX( temp_file!$B$1:$B$180,MATCH($D2,temp_file!$A$1:$A$180,0)), "#N/A" ) -> D1 | D2: RESETN | E2: 1.8V (不可配） | F2: RESETN | N2: RESETN | O2: RESETN | P2: RESETN | Q2: RESETN | R2: RESETN | S2: RESETN
A3: CLK_IN | B3: PDXOEDG_H_G | C3: =IFERROR( INDEX( temp_file!$B$1:$B$180,MATCH($D3,temp_file!$A$1:$A$180,0)), "#N/A" ) -> E1 | D3: CLK_IN | E3: 1.8V (不可配） | F3: CLK_IN | N3: CLK_IN | O3: CLK_IN | P3: CLK_IN | Q3: CLK_IN | R3: CLK_IN | S3: CLK_IN
A4: CLK | B4: PDXOEDG_H_G | C4: =IFERROR( INDEX( temp_file!$B$1:$B$180,MATCH($D4,temp_file!$A$1:$A$180,0)), "#N/A" ) -> E2 | D4: CLK | E4: 1.8V (不可配） | F4: CLK_OUT | N4: CLK_OUT | O4: CLK_OUT | P4: CLK_OUT | Q4: CLK_OUT | R4: CLK_OUT | S4: CLK_OUT
C5: =IFERROR( INDEX( temp_file!$B$1:$B$180,MATCH($D5,temp_file!$A$1:$A$180,0)), "#N/A" ) -> V4 | D5: BOOT_MODE | E5: 3.3V | F5: GPIO30 | N5: BOOT_MODE | O5: BOOT_MODE | P5: BOOT_MODE | Q5: BOOT_MODE | R5: BOOT_MODE | S5: BOOT_MODE
C6: =IFERROR( INDEX( temp_file!$B$1:$B$180,MATCH($D6,temp_file!$A$1:$A$180,0)), "#N/A" ) -> W4 | D6: BOOT_SEL1 | E6: 3.3V | F6: GPIO31 | G6: ETH_LINK_ACT_LED | N6: BOOT_SEL1 | O6: BOOT_SEL1 | P6: BOOT_SEL1 | Q6: BOOT_SEL1 | R6: BOOT_SEL1 | S6: BOOT_SEL1
C7: =IFERROR( INDEX( temp_file!$B$1:$B$180,MATCH($D7,temp_file!$A$1:$A$180,0)), "#N/A" ) -> Y4 | D7: BOOT_SEL0 | E7: 3.3V | F7: GPIO32 | G7: ETH_LINK_STA_LED | H7: ETH_LINK_SPD_LED | N7: BOOT_SEL0 | O7: BOOT_SEL0 | P7: BOOT_SEL0 | Q7: BOOT_SEL0 | R7: BOOT_SEL0 | S7: BOOT_SEL0
C8: =IFERROR( INDEX( temp_file!$B$1:$B$180,MATCH($D8,temp_file!$A$1:$A$180,0)), "#N/A" ) -> H16 | D8: UART0_TX | E8: 3.3V | F8: UART0_TX | G8: GPIO33 | N8: UART0_TX | O8: UART0_TX | P8: UART0_TX | Q8: UART0_TX | R8: UART0_TX | S8: UART0_TX
C9: =IFERROR( INDEX( temp_file!$B$1:$B$180,MATCH($D9,temp_file!$A$1:$A$180,0)), "#N/A" ) -> J15 | D9: UART0_RX | E9: 3.3V | F9: UART0_RX | G9: GPIO34 | N9: UART0_RX | O9: UART0_RX | P9: UART0_RX | Q9: UART0_RX | R9: UART0_RX | S9: UART0_RX
A10: I2C0_SDA | B10: PRWHSWCDGSD_H | C10: =IFERROR( INDEX( temp_file!$B$1:$B$180,MATCH($D10,temp_file!$A$1:$A$180,0)), "#N/A" ) -> R16 | D10: I2C0_SCL | E10: 1.8V (不可配） | F10: I2C0_SCL | G10: GPIO35 | N10: I2C0_SCL | O10: I2C0_SCL | P10: I2C0_SCL | Q10: I2C0_SCL | R10: I2C0_SCL | S10: I2C0_SCL
A11: I2C0_SCL | B11: PRWHSWCDGSD_H | C11: =IFERROR( INDEX( temp_file!$B$1:$B$180,MATCH($D11,temp_file!$A$1:$A$180,0)), "#N/A" ) -> R17 | D11: I2C0_SDA | E11: 1.8V (不可配） | F11: I2C0_SDA | G11: GPIO36 | N11: I2C0_SDA | O11: I2C0_SDA | P11: I2C0_SDA | Q11: I2C0_SDA | R11: I2C0_SDA | S11: I2C0_SDA
A12: GPIO_12 | B12: PRWHSWCDGSD_H | C12: =IFERROR( INDEX( temp_file!$B$1:$B$180,MATCH($D12,temp_file!$A$1:$A$180,0)), "#N/A" ) -> R18 | D12: SENSOR_CLK | E12: 1.8V (不可配） | F12: SENSOR_CLK | G12: GPIO12 | N12: SENSOR_CLK | O12: SENSOR_CLK | P12: SENSOR_CLK | Q12: SENSOR_CLK | R12: SENSOR_CLK | S12: SENSOR_CLK
A13: GPIO_13 | B13: PRWHSWCDGSD_H | C13: =IFERROR( INDEX( temp_file!$B$1:$B$180,MATCH($D13,temp_file!$A$1:$A$180,0)), "#N/A" ) -> P16 | D13: SENSOR_RSTN | E13: 1.8V (不可配） | F13: GPIO13 | N13: SENSOR_RSTN | O13: SENSOR_RSTN | P13: SENSOR_RSTN | Q13: SENSOR_RSTN | R13: SENSOR_RSTN | S13: SENSOR_RSTN
A14: GPIO_14 | B14: PRWHSWCDGSD_H | C14: =IFERROR( INDEX( temp_file!$B$1:$B$180,MATCH($D14,temp_file!$A$1:$A$180,0)), "#N/A" ) -> N2 | D14: UART1_TX | E14: 3.3V | F14: UART1_TX | G14: GPIO39 | H14: PWM10 | I14: SD1_CLK | N14: UART1_TX | O14: UART1_TX | P14: UART1_TX | Q14: UART1_TX | R14: UART1_TX | S14: AF1_NSLEEP
A15: MAC_REF_CLK | B15: PRWHSWCDGSD_H | C15: =IFERROR( INDEX( temp_file!$B$1:$B$180,MATCH($D15,temp_file!$A$1:$A$180,0)), "#N/A" ) -> N1 | D15: UART1_RX | E15: 3.3V | F15: UART1_RX | G15: GPIO40 | H15: PWM11 | I15: SD1_CD | N15: UART1_RX | O15: UART1_RX | P15: UART1_RX | Q15: UART1_RX | R15: UART1_RX | S15: AF2_NSLEEP
A16: MAC_RMII_CLK | B16: PRWHSWCDGSD_H | C16: =IFERROR( INDEX( temp_file!$B$1:$B$180,MATCH($D16,temp_file!$A$1:$A$180,0)), "#N/A" ) -> M2 | D16: I2C1_SCL | E16: 3.3V | F16: I2C1_SCL | G16: GPIO37 | H16: PWM2 | I16: SD1_CMD_RSP | J16: STM_H_0 | K16: SSI1_CLK | N16: 电机 SSI1_CLK | O16: 水平电机 SSI1_CLK | P16: 水平电机 PWM2 | Q16: PWM2 | R16: 水平电机 PWM2 | S16: 电机 PWM2
A17: MAC_RXD_0 | B17: PRWHSWCDGSD_H | C17: =IFERROR( INDEX( temp_file!$B$1:$B$180,MATCH($D17,temp_file!$A$1:$A$180,0)), "#N/A" ) -> L1 | D17: I2C1_SDA | E17: 3.3V | F17: I2C1_SDA | G17: GPIO38 | H17: PWM3 | I17: SD1_DATA_0 | J17: STM_H_1 | K17: SSI1_CSN_0 | N17: 电机 SSI1_CSN_0 | O17: 水平电机 SSI1_CSN_0 | P17: 水平电机 PWM3 | Q17: PWM3 | R17: 水平电机 PWM3 | S17: 电机 PWM3
A18: MAC_RXD_1 | B18: PRWHSWCDGSD_H | C18: =IFERROR( INDEX( temp_file!$B$1:$B$180,MATCH($D18,temp_file!$A$1:$A$180,0)), "#N/A" ) -> L3 | D18: UART2_TX | E18: 3.3V | F18: UART2_TX | G18: GPIO41 | H18: PWM4 | I18: SD1_DATA_1 | J18: STM_H_2 | K18: SSI1_TXD | N18: 电机 SSI1_TXD | O18: 水平电机 SSI1_TXD | P18: 水平电机 PWM4 | Q18: PWM4 | R18: 水平电机 PWM4 | S18: 电机 PWM4/UART2_TX
A19: MAC_RXDV | B19: PRWHSWCDGSD_H | C19: =IFERROR( INDEX( temp_file!$B$1:$B$180,MATCH($D19,temp_file!$A$1:$A$180,0)), "#N/A" ) -> K3 | D19: UART2_RX | E19: 3.3V | F19: UART2_RX | G19: GPIO42 | H19: PWM5 | I19: SD1_DATA_2 | J19: STM_H_3 | K19: SSI1_RXD | N19: 电机 SSI1_RXD | O19: 水平电机 SSI1_RXD | P19: 水平电机 PWM5 | Q19: PWM5 | R19: 水平电机 PWM5 | S19: 电机 PWM5/UART2_RX
A20: MAC_TXD_0 | B20: PRWHSWCDGSD_H | C20: =IFERROR( INDEX( temp_file!$B$1:$B$180,MATCH($D20,temp_file!$A$1:$A$180,0)), "#N/A" ) -> P2 | D20: USB_PWREN | E20: 3.3V | F20: USB_PWREN | G20: GPIO47 | I20: SD1_DATA_3 | N20: USB_PWREN | O20: USB_PWREN | P20: USB_PWREN | Q20: USB_PWREN | R20: USB_PWREN | S20: USB_PWREN(WIFI&4G RESET)
A21: MAC_TXD_1 | B21: PRWHSWCDGSD_H | C21: =IFERROR( INDEX( temp_file!$B$1:$B$180,MATCH($D21,temp_file!$A$1:$A$180,0)), "#N/A" ) -> G16 | D21: PWM0 | E21: 3.3V | F21: PWM0 | G21: GPIO43 | H21: I2C2_SCL | I21: UART2_TX | N21: VD_FZ | O21: VD_FZ | P21: ICR_ON | Q21: ICR_ON/WIFI_INT/AK7755复位 | R21: ICR_ON | S21: W_LIGHT（白光PWM）
A22: MAC_TXEN | B22: PRWHSWCDGSD_H | C22: =IFERROR( INDEX( temp_file!$B$1:$B$180,MATCH($D22,temp_file!$A$1:$A$180,0)), "#N/A" ) -> F16 | D22: PWM1 | E22: 3.3V | F22: PWM1 | G22: GPIO44 | H22: I2C2_SDA | I22: UART2_RX | N22: 出厂复位 | O22: 出厂复位 | P22: 出厂复位 | Q22: 出厂复位/WL_REG_ON | R22: 出厂复位 | S22: IR_LIGHT (红外PWM)
A23: MAC_MDC | B23: PRWHSWCDGSD_H | C23: =IFERROR( INDEX( temp_file!$B$1:$B$180,MATCH($D23,temp_file!$A$1:$A$180,0)), "#N/A" ) -> M3 | D23: PWM2 | E23: 3.3V | F23: PWM2 | G23: GPIO45 | Q23: PWM2 | R23: SD0卡使能
A24: MAC_MDIO | B24: PRWHSWCDGSD_H | C24: =IFERROR( INDEX( temp_file!$B$1:$B$180,MATCH($D24,temp_file!$A$1:$A$180,0)), "#N/A" ) -> N3 | D24: PWM3 | E24: 3.3V | F24: PWM3 | G24: GPIO46 | Q24: PWM3 | R24: SD1卡使能
A25: SD0_CD | B25: PRWHSWCDGSD_H | C25: Y8 | D25: MAC_RMII_CLK | E25: 3.3V | F25: MAC_RMII_CLK | G25: GPIO48 | H25: SD1_CLK | I25: PWM2 | J25: STM_H_0 | N25: #N/A | O25: #N/A | P25: #N/A | Q25: MAC_RMII_CLK | R25: MAC_RMII_CLK
A26: SD0_CMD_RSP | B26: PRWHSWCDGSD_H | C26: =IFERROR( INDEX( temp_file!$B$1:$B$180,MATCH($D26,temp_file!$A$1:$A$180,0)), "#N/A" ) -> V9 | D26: MAC_TXD_0 | E26: 3.3V | F26: MAC_TXD_0 | G26: GPIO49 | H26: SD1_CD | I26: PWM3 | J26: STM_H_1 | N26: #N/A | O26: #N/A | P26: #N/A | Q26: MAC_TXD_0 | R26: MAC_TXD_0
A27: SD0_DATA_0 | B27: PRWHSWCDGSD_H | C27: =IFERROR( INDEX( temp_file!$B$1:$B$180,MATCH($D27,temp_file!$A$1:$A$180,0)), "#N/A" ) -> U9 | D27: MAC_TXD_1 | E27: 3.3V | F27: MAC_TXD_1 | G27: GPIO50 | H27: SD1_CMD_RSP | I27: PWM4 | J27: STM_H_2 | N27: #N/A | O27: #N/A | P27: #N/A | Q27: MAC_TXD_1 | R27: MAC_TXD_1
A28: SD0_DATA_1 | B28: PRWHSWCDGSD_H | C28: =IFERROR( INDEX( temp_file!$B$1:$B$180,MATCH($D28,temp_file!$A$1:$A$180,0)), "#N/A" ) -> W9 | D28: MAC_TXEN | E28: 3.3V | F28: MAC_TXEN | G28: GPIO51 | H28: SD1_DATA_0 | I28: PWM5 | J28: STM_H_3 | N28: #N/A | O28: #N/A | P28: #N/A | Q28: MAC_TXEN | R28: MAC_TXEN
A29: SD0_DATA_2 | B29: PRWHSWCDGSD_H | C29: =IFERROR( INDEX( temp_file!$B$1:$B$180,MATCH($D29,temp_file!$A$1:$A$180,0)), "#N/A" ) -> V8 | D29: MAC_RXD_0 | E29: 3.3V | F29: MAC_RXD_0 | G29: GPIO52 | H29: SD1_DATA_1 | I29: PWM6 | J29: STM_V_0 | N29: #N/A | O29: #N/A | P29: #N/A | Q29: MAC_RXD_0 | R29: MAC_RXD_0
A30: SD0_DATA_3 | B30: PRWHSWCDGSD_H | C30: =IFERROR( INDEX( temp_file!$B$1:$B$180,MATCH($D30,temp_file!$A$1:$A$180,0)), "#N/A" ) -> W8 | D30: MAC_RXD_1 | E30: 3.3V | F30: MAC_RXD_1 | G30: GPIO53 | H30: SD1_DATA_2 | I30: PWM7 | J30: STM_V_1 | N30: #N/A | O30: #N/A | P30: #N/A | Q30: MAC_RXD_1 | R30: MAC_RXD_1
A31: SD0_WP | B31: PRWHSWCDGSD_H | C31: =IFERROR( INDEX( temp_file!$B$1:$B$180,MATCH($D31,temp_file!$A$1:$A$180,0)), "#N/A" ) -> Y9 | D31: MAC_RXDV | E31: 3.3V | F31: MAC_RXDV | G31: GPIO54 | H31: SD1_DATA_3 | I31: PWM8 | J31: STM_V_2 | N31: #N/A | O31: #N/A | P31: #N/A | Q31: MAC_RXDV | R31: MAC_RXDV
A32: GPIO_0 | B32: PRWHSWCDGSD_H | C32: =IFERROR( INDEX( temp_file!$B$1:$B$180,MATCH($D32,temp_file!$A$1:$A$180,0)), "#N/A" ) -> U8 | D32: MAC_MDC | E32: 3.3V | F32: MAC_MDC | G32: GPIO55 | I32: PWM9 | J32: STM_V_3 | N32: #N/A | O32: #N/A | P32: #N/A | Q32: MAC_MDC | R32: MAC_MDC
A33: GPIO_1 | B33: PRWHSWCDGSD_H | C33: =IFERROR( INDEX( temp_file!$B$1:$B$180,MATCH($D33,temp_file!$A$1:$A$180,0)), "#N/A" ) -> V7 | D33: MAC_MDIO | E33: 3.3V | F33: MAC_MDIO | G33: GPIO56 | N33: #N/A | O33: #N/A | P33: #N/A | Q33: MAC_MDIO | R33: MAC_MDIO
A34: GPIO_2 | B34: PRWHSWCDGSD_H | C34: =IFERROR( INDEX( temp_file!$B$1:$B$180,MATCH($D34,temp_file!$A$1:$A$180,0)), "#N/A" ) -> V13 | D34: SD1_CLK | E34: 3.3V | F34: SD1_CLK | G34: GPIO57 | H34: I2C1_SCL | N34: #N/A | O34: #N/A | P34: #N/A | Q34: SD1_CLK | R34: SD1_CLK
A35: GPIO_3 | B35: PRWHSWCDGSD_H | C35: =IFERROR( INDEX( temp_file!$B$1:$B$180,MATCH($D35,temp_file!$A$1:$A$180,0)), "#N/A" ) -> V14 | D35: SD1_CD | E35: 3.3V | F35: SD1_CD | G35: GPIO58 | H35: I2C1_SDA | N35: #N/A | O35: #N/A | P35: #N/A | Q35: SD1_CD | R35: SD1_CD
A36: GPIO_4 | B36: PRWHSWCDGSD_H | C36: =IFERROR( INDEX( temp_file!$B$1:$B$180,MATCH($D36,temp_file!$A$1:$A$180,0)), "#N/A" ) -> U13 | D36: SD1_CMD_RSP | E36: 3.3V | F36: SD1_CMD_RSP | G36: GPIO59 | H36: UART1_TX | N36: #N/A | O36: #N/A | P36: #N/A | Q36: SD1_CMD_RSP | R36: SD1_CMD_RSP
A37: GPIO_5 | B37: PRWHSWCDGSD_H | C37: =IFERROR( INDEX( temp_file!$B$1:$B$180,MATCH($D37,temp_file!$A$1:$A$180,0)), "#N/A" ) -> U12 | D37: SD1_DATA_0 | E37: 3.3V | F37: SD1_DATA_0 | G37: GPIO60 | H37: UART1_RX | N37: #N/A | O37: s | P37: #N/A | Q37: SD1_DATA_0 | R37: SD1_DATA_0
A38: GPIO_6 | B38: PRWHSWCDGSD_H | C38: =IFERROR( INDEX( temp_file!$B$1:$B$180,MATCH($D38,temp_file!$A$1:$A$180,0)), "#N/A" ) -> V12 | D38: SD1_DATA_1 | E38: 3.3V | F38: SD1_DATA_1 | G38: GPIO61 | H38: UART2_TX | N38: #N/A | O38: #N/A | P38: #N/A | Q38: SD1_DATA_1 | R38: SD1_DATA_1
A39: GPIO_7 | B39: PRWHSWCDGSD_H | C39: =IFERROR( INDEX( temp_file!$B$1:$B$180,MATCH($D39,temp_file!$A$1:$A$180,0)), "#N/A" ) -> V11 | D39: SD1_DATA_2 | E39: 3.3V | F39: SD1_DATA_2 | G39: GPIO62 | H39: UART2_RX | N39: #N/A | O39: #N/A | P39: #N/A | Q39: SD1_DATA_2 | R39: SD1_DATA_2
A40: GPIO_8 | B40: PRWHSWCDGSD_H | C40: =IFERROR( INDEX( temp_file!$B$1:$B$180,MATCH($D40,temp_file!$A$1:$A$180,0)), "#N/A" ) -> U11 | D40: SD1_DATA_3 | E40: 3.3V | F40: SD1_DATA_3 | G40: GPIO63 | N40: #N/A | O40: #N/A | P40: #N/A | Q40: SD1_DATA_3 | R40: SD1_DATA_3
...

Sheet 管脚分布
B1: 1 | C1: 2 | D1: 3 | E1: 4 | F1: 5 | G1: 6 | H1: 7 | I1: 8 | J1: 9 | K1: 10 | L1: 11 | M1: 12 | N1: 13 | O1: 14 | P1: 15 | Q1: 16 | R1: 17 | S1: 18
A2: A | B2: VSS | C2: DDR_ODT | D2: DDR_A14 | F2: DDR_A1 | G2: DDR_BA1 | I2: DDR_CKE | J2: DDR_CLK_N | L2: DDR_DQ1 | N2: DDR_DQ4 | P2: DDR_DQS1_P | Q2: DDR_DQS0_N | R2: VSS | S2: VSS
A3: B | B3: DDR_CAL | C3: DDR_CS_N | D3: DDR_A11 | E3: DDR_A8 | F3: DDR_A6 | G3: DDR_A4 | H3: VSS | I3: DDR_A10 | J3: DDR_CLK_P | K3: VSS | L3: DDR_DQ5 | M3: DDR_DQ3 | N3: DDR_DQ14 | O3: DDR_DQ12 | P3: DDR_DQS1_N | Q3: DDR_DQS0_P | R3: DDR_DQ15 | S3: DDR_DM1
A4: C | B4: DDR_ZQ | C4: VSS | D4: DDR_A5 | E4: VSS | F4: DDR_A7 | G4: DDR_A12 | H4: DDR_A3 | I4: DDR_A0 | J4: VSS | K4: DDR_WE_N | L4: DDR_CAS_N | M4: VSS | N4: DDR_DQ6 | O4: VSS | P4: DDR_DQ8 | Q4: DDR_DQ0 | R4: DDR_DQ13 | S4: DDR_DQ11
A5: D | B5: RESETN | C5: VSS | D5: DDR_RESET_N | E5: DDR_A13 | F5: VSS | G5: DDR_A9 | H5: VSS | I5: VSS | J5: DDR_BA2 | K5: VSS | L5: VSS | M5: DDR_DQ7 | N5: VSS | O5: DDR_DM0 | P5: VSS | Q5: DDR_DQ9 | R5: VSS | S5: DDR_DQ2
A6: E | B6: CLK_IN | C6: CLK | D6: GNDA_PLL | E6: VDDA09_PLL | G6: DDR_VREFDQ | H6: DDR_A2 | I6: VSS | J6: VSS | K6: DDR_BA0 | L6: VSS | M6: DDR_RAS_N | N6: VSS | O6: DDR_DQ10 | P6: VSS | Q6: VSS | R6: SSI0_D3 | S6: SSI0_D2
A7: F | C7: VSS | D7: VSS | E7: VDDA18_PLL | H7: VDDIO_DDR | I7: VDDIO_DDR | J7: VDDIO_DDR | K7: VSS | L7: VDDIO_DDR | M7: VDDIO_DDR | N7: VDDIO_DDR | O7: VDDIO_DDR | P7: VSS | Q7: PWM1 | R7: SSI0_RXD | S7: SSI0_TXD
A8: G | B8: XIN_RTC | C8: XOUT_RTC | D8: GNDA_RTC | E8: VDDA33_RTC | P8: VDDIO_18OD33 | Q8: PWM0 | R8: SSI0_CSN_0 | S8: SSI0_CLK
A9: H | C9: GNDA_RTC | D9: GPIO1 | P9: VDDIO_18 | Q9: UART0_TX | R9: VSS
A10: J | B10: GPIO3 | C10: GPIO2 | D10: GPIO0 | G10: VSS | H10: VSS | I10: VDDIO_CLK | J10: VSS | K10: VSS | L10: VSS | M10: VSS | P10: UART0_RX | Q10: GNDA_AC | R10: MICINN_AC | S10: MICINP_AC
A11: K | C11: GPIO4 | D11: UART2_RX | G11: VSS | H11: VSS | I11: VSS | J11: VSS | K11: VDDK_DDR | L11: VDDK_DDR | M11: VSS | P11: LINE1_AC | Q11: LOUT_AC | R11: MICBIAS_AC | S11: VMID_AC
A12: L | B12: I2C1_SDA | C12: VSS | D12: UART2_TX | E12: VDDIO_18OD33 | G12: VSS | H12: VSS | I12: VDDK | J12: VDDK | K12: VDDK | L12: VDDK | M12: VSS | P12: VDDA_AC | Q12: GNDA_AC | R12: NC | S12: NC | V12: FH8858v310只有一组差分MIC，另外2组为NC处理，预留是为了兼容FH8658
A13: M | C13: I2C1_SCL | D13: PWM2 | G13: VSS | H13: VSS | I13: VDDK | J13: VDDK | K13: VDDK | L13: VDDK | M13: VSS | P13: XAIN0_SADC | Q13: GNDA_AC | R13: NC | S13: NC
A14: N | B14: UART1_RX | C14: UART1_TX | D14: PWM3 | G14: VSS | H14: VSS | I14: VSS | J14: VSS | K14: VSS | L14: VSS | M14: VSS | P14: XAIN2_SADC | Q14: XAIN1_SADC | R14: NC | S14: NC
A15: P | B15: USB_VBUS | C15: USB_PWREN | D15: VDDA33_USB | E15: VDDA18_USB | G15: VSS | H15: VSS | I15: VSS | J15: VSS | K15: VSS | L15: VSS | M15: VSS | P15: XAIN3_SADC | Q15: SENSOR_RSTN | R15: VSS
A16: R | B16: USB_DM | C16: USB_DP | D16: GNDA_USB | E16: VDDA09_EPHY | P16: VDDIO_18 | Q16: I2C0_SCL | R16: I2C0_SDA | S16: SENSOR_CLK
A17: T | B17: USB_REXT | C17: GNDA_USB | D17: GNDA_USB | E17: VDDA33_EPHY | P17: VDDA_MIPI | Q17: GNDA_MIPI | R17: REXT_MIPI
A18: U | C18: GNDA_USB | D18: GNDA_EPHY | E18: GNDA_EPHY | F18: VDDA12_VREF | G18: VDDIO_18 | I18: MAC_MDC | J18: MAC_TXD_1 | K18: VDDIO_18OD33 | L18: SD1_DATA_3 | M18: SD1_DATA_0 | N18: SD1_CMD_RSP | P18: VDDA_MIPI | Q18: GNDA_MIPI | R18: DP3_MIPI | S18: DN3_MIPI
A19: V | B19: EPHY_ATBUSA | C19: EPHY_ATBUSB | D19: GNDA_EPHY | E19: BOOT_MODE | F19: VDDA18_EPHY | G19: SSI1_CSN_0 | H19: MAC_MDIO | I19: MAC_RXD_0 | J19: MAC_TXD_0 | K19: VSS | L19: SD1_DATA_2 | M19: SD1_DATA_1 | N19: SD1_CLK | O19: SD1_CD | P19: GNDA_MIPI | Q19: GNDA_MIPI | R19: DP2_MIPI | S19: DN2_MIPI
A20: W | B20: EPHY_RTX | C20: EPHY_RXN | D20: EPHY_TXN | E20: BOOT_SEL1 | F20: VSS | G20: SSI1_TXD | H20: VSS | I20: MAC_RXD_1 | J20: MAC_TXEN | K20: GPIO28 | L20: SD0_DATA_2 | M20: SD0_DATA_0 | N20: VSS | O20: SD0_CMD_RSP | P20: DN0_MIPI | Q20: DN1_MIPI | R20: CKN_MIPI
A21: Y | C21: EPHY_RXP | D21: EPHY_TXP | E21: BOOT_SEL0 | F21: SSI1_CLK | G21: SSI1_RXD | I21: MAC_CLK | J21: MAC_RXDV | K21: GPIO29 | L21: SD0_DATA_3 | M21: SD0_DATA_1 | N21: SD0_CLK | O21: SD0_CD | P21: DP0_MIPI | Q21: DP1_MIPI | R21: CKP_MIPI
V24: FH8858v310外置DDR3颗粒 VDDIO_DDR电源 | W24: 1.35V

Sheet IO_STATUS
A1: FH8858v310 Pin_num | B1: PAD Name | C1: Default Function | D1: Default MFS [27:24] | E1: IO电源已上电，CORE电源未上电 | G1: IO/CORE电源已上电，复位撤销之前 | I1: IO电源和CORE都已上电，复位撤销之后，ROM开始执行到结束期间。 | K1: ScanPU | L1: ScanPD
E2: 电平状态 | F2: I/O类型 | G2: 电平状态 | H2: I/O类型 | I2: 电平状态 | J2: I/O类型 | K2: 电平状态 | L2: 电平状态
A3: =PIN_MUX!C2 -> D1 | B3: =PIN_MUX!D2 -> RESETN | C3: =[1]PIN_MUX!K6 -> RESETN | D3: N/A | E3: HiZ | F3: NA | G3: PU | H3: I | I3: PU | J3: I | K3: PU=1 | L3: PD=0
A4: =PIN_MUX!C3 -> E1 | B4: =PIN_MUX!D3 -> CLK_IN | C4: =[1]PIN_MUX!K8 -> CLK_IN | D4: N/A | E4: HiZ | F4: NA | G4: HiZ | H4: I | I4: 0/1 | J4: I | K4: - | L4: -
A5: =PIN_MUX!C4 -> E2 | B5: =PIN_MUX!D4 -> CLK | C5: =[1]PIN_MUX!K9 -> CLK_OUT | D5: N/A | E5: HiZ | F5: NA | G5: X | H5: O | I5: 0/1 | J5: O | K5: - | L5: -
A6: =PIN_MUX!C5 -> V4 | B6: =PIN_MUX!D5 -> BOOT_MODE | C6: =[1]PIN_MUX!K10 -> GPIO30 | D6: Func0 | E6: HiZ | F6: NA | G6: PU | H6: I | I6: PU | J6: I | K6: PU=0 | L6: PD=0
A7: =PIN_MUX!C6 -> W4 | B7: =PIN_MUX!D6 -> BOOT_SEL1 | C7: =[1]PIN_MUX!K11 -> GPIO31 | D7: Func0 | E7: HiZ | F7: NA | G7: PU | H7: I | I7: PU | J7: I | K7: PU=0 | L7: PD=0
A8: =PIN_MUX!C7 -> Y4 | B8: =PIN_MUX!D7 -> BOOT_SEL0 | C8: =[1]PIN_MUX!K12 -> GPIO32 | D8: Func0 | E8: HiZ | F8: NA | G8: PU | H8: I | I8: PU | J8: I | K8: PU=0 | L8: PD=0
A9: =PIN_MUX!C8 -> H16 | B9: =PIN_MUX!D8 -> UART0_TX | C9: =[1]PIN_MUX!K13 -> UART0_TX | D9: Func0 | E9: HiZ | F9: NA | G9: H | H9: O | I9: 0/1 | J9: O | K9: PU=0 | L9: PD=0
A10: =PIN_MUX!C9 -> J15 | B10: =PIN_MUX!D9 -> UART0_RX | C10: =[1]PIN_MUX!K14 -> UART0_RX | D10: Func0 | E10: HiZ | F10: NA | G10: PU | H10: I | I10: 0/1 | J10: I | K10: PU=0 | L10: PD=0 | M10: autoload: 常0 安全模式：会翻转
A11: =PIN_MUX!C10 -> R16 | B11: =PIN_MUX!D10 -> I2C0_SCL | C11: =[1]PIN_MUX!L15 -> GPIO35 | D11: Func1 | E11: HiZ | F11: NA | G11: PU | H11: I | I11: PU | J11: I | K11: PU=0 | L11: PD=0
A12: =PIN_MUX!C11 -> R17 | B12: =PIN_MUX!D11 -> I2C0_SDA | C12: =[1]PIN_MUX!L16 -> GPIO36 | D12: Func1 | E12: HiZ | F12: NA | G12: PU | H12: I | I12: PU | J12: I | K12: PU=0 | L12: PD=0
A13: =PIN_MUX!C12 -> R18 | B13: =PIN_MUX!D12 -> SENSOR_CLK | C13: =[1]PIN_MUX!L17 -> GPIO12 | D13: Func1 | E13: HiZ | F13: NA | G13: HiZ | H13: I | I13: HiZ | J13: I | K13: PU=0 | L13: PD=0
A14: =PIN_MUX!C13 -> P16 | B14: =PIN_MUX!D13 -> SENSOR_RSTN | C14: =[1]PIN_MUX!K18 -> GPIO13 | D14: Func0 | E14: HiZ | F14: NA | G14: HiZ | H14: I | I14: HiZ | J14: I | K14: PU=0 | L14: PD=0
A15: =PIN_MUX!C14 -> N2 | B15: =PIN_MUX!D14 -> UART1_TX | C15: =[1]PIN_MUX!L20 -> GPIO39 | D15: Func1 | E15: HiZ | F15: NA | G15: HiZ | H15: I | I15: HiZ | J15: I | K15: PU=0 | L15: PD=0
A16: =PIN_MUX!C15 -> N1 | B16: =PIN_MUX!D15 -> UART1_RX | C16: =[1]PIN_MUX!L21 -> GPIO40 | D16: Func1 | E16: HiZ | F16: NA | G16: HiZ | H16: I | I16: HiZ | J16: I | K16: PU=0 | L16: PD=0
A17: =PIN_MUX!C16 -> M2 | B17: =PIN_MUX!D16 -> I2C1_SCL | C17: =[1]PIN_MUX!L22 -> GPIO37 | D17: Func1 | E17: HiZ | F17: NA | G17: HiZ | H17: I | I17: HiZ | J17: I | K17: PU=0 | L17: PD=0
A18: =PIN_MUX!C17 -> L1 | B18: =PIN_MUX!D17 -> I2C1_SDA | C18: =[1]PIN_MUX!L23 -> GPIO38 | D18: Func1 | E18: HiZ | F18: NA | G18: HiZ | H18: I | I18: HiZ | J18: I | K18: PU=0 | L18: PD=0
A19: =PIN_MUX!C18 -> L3 | B19: =PIN_MUX!D18 -> UART2_TX | C19: =[1]PIN_MUX!L24 -> GPIO41 | D19: Func1 | E19: HiZ | F19: NA | G19: HiZ | H19: I | I19: HiZ | J19: I | K19: PU=0 | L19: PD=0
A20: =PIN_MUX!C19 -> K3 | B20: =PIN_MUX!D19 -> UART2_RX | C20: =[1]PIN_MUX!L25 -> GPIO42 | D20: Func1 | E20: HiZ | F20: NA | G20: HiZ | H20: I | I20: HiZ | J20: I | K20: PU=0 | L20: PD=0
A21: =PIN_MUX!C20 -> P2 | B21: =PIN_MUX!D20 -> USB_PWREN | C21: =[1]PIN_MUX!L26 -> GPIO47 | D21: Func1 | E21: HiZ | F21: NA | G21: HiZ | H21: I | I21: HiZ | J21: I | K21: PU=0 | L21: PD=0
A22: =PIN_MUX!C21 -> G16 | B22: =PIN_MUX!D21 -> PWM0 | C22: =[1]PIN_MUX!L27 -> GPIO43 | D22: Func1 | E22: HiZ | F22: NA | G22: HiZ | H22: I | I22: HiZ | J22: I | K22: PU=0 | L22: PD=0
A23: =PIN_MUX!C22 -> F16 | B23: =PIN_MUX!D22 -> PWM1 | C23: =[1]PIN_MUX!L28 -> GPIO44 | D23: Func1 | E23: HiZ | F23: NA | G23: HiZ | H23: I | I23: HiZ | J23: I | K23: PU=0 | L23: PD=0
A24: =PIN_MUX!C23 -> M3 | B24: =PIN_MUX!D23 -> PWM2 | C24: =[1]PIN_MUX!L29 -> GPIO45 | D24: Func1 | E24: HiZ | F24: NA | G24: HiZ | H24: I | I24: HiZ | J24: I | K24: PU=0 | L24: PD=0
A25: =PIN_MUX!C24 -> N3 | B25: =PIN_MUX!D24 -> PWM3 | C25: =[1]PIN_MUX!L30 -> GPIO46 | D25: Func1 | E25: HiZ | F25: NA | G25: HiZ | H25: I | I25: HiZ | J25: I | K25: PU=0 | L25: PD=0
A26: =PIN_MUX!C25 -> Y8 | B26: =PIN_MUX!D25 -> MAC_RMII_CLK | C26: =[1]PIN_MUX!L31 -> GPIO48 | D26: Func1 | E26: HiZ | F26: NA | G26: L | H26: O | I26: 0/1 | J26: O | K26: PU=0 | L26: PD=0
A27: =PIN_MUX!C26 -> V9 | B27: =PIN_MUX!D26 -> MAC_TXD_0 | C27: =[1]PIN_MUX!L33 -> GPIO49 | D27: Func1 | E27: HiZ | F27: NA | G27: HiZ | H27: I | I27: HiZ | J27: I | K27: PU=0 | L27: PD=0
A28: =PIN_MUX!C27 -> U9 | B28: =PIN_MUX!D27 -> MAC_TXD_1 | C28: =[1]PIN_MUX!L34 -> GPIO50 | D28: Func1 | E28: HiZ | F28: NA | G28: HiZ | H28: I | I28: HiZ | J28: I | K28: PU=0 | L28: PD=0
A29: =PIN_MUX!C28 -> W9 | B29: =PIN_MUX!D28 -> MAC_TXEN | C29: =[1]PIN_MUX!L35 -> GPIO51 | D29: Func1 | E29: HiZ | F29: NA | G29: HiZ | H29: I | I29: HiZ | J29: I | K29: PU=0 | L29: PD=0
A30: =PIN_MUX!C29 -> V8 | B30: =PIN_MUX!D29 -> MAC_RXD_0 | C30: =[1]PIN_MUX!L36 -> GPIO52 | D30: Func1 | E30: HiZ | F30: NA | G30: HiZ | H30: I | I30: HiZ | J30: I | K30: PU=0 | L30: PD=0
A31: =PIN_MUX!C30 -> W8 | B31: =PIN_MUX!D30 -> MAC_RXD_1 | C31: =[1]PIN_MUX!L37 -> GPIO53 | D31: Func1 | E31: HiZ | F31: NA | G31: HiZ | H31: I | I31: HiZ | J31: I | K31: PU=0 | L31: PD=0
A32: =PIN_MUX!C31 -> Y9 | B32: =PIN_MUX!D31 -> MAC_RXDV | C32: =[1]PIN_MUX!L38 -> GPIO54 | D32: Func1 | E32: HiZ | F32: NA | G32: HiZ | H32: I | I32: HiZ | J32: I | K32: PU=0 | L32: PD=0
A33: =PIN_MUX!C32 -> U8 | B33: =PIN_MUX!D32 -> MAC_MDC | C33: =[1]PIN_MUX!L39 -> GPIO55 | D33: Func1 | E33: HiZ | F33: NA | G33: HiZ | H33: I | I33: HiZ | J33: I | K33: PU=0 | L33: PD=0
A34: =PIN_MUX!C33 -> V7 | B34: =PIN_MUX!D33 -> MAC_MDIO | C34: =[1]PIN_MUX!L40 -> GPIO56 | D34: Func1 | E34: HiZ | F34: NA | G34: HiZ | H34: I | I34: HiZ | J34: I | K34: PU=0 | L34: PD=0
A35: =PIN_MUX!C34 -> V13 | B35: =PIN_MUX!D34 -> SD1_CLK | C35: =[1]PIN_MUX!L41 -> GPIO57 | D35: Func1 | E35: HiZ | F35: NA | G35: HiZ | H35: I | I35: HiZ | J35: I | K35: PU=0 | L35: PD=0
A36: =PIN_MUX!C35 -> V14 | B36: =PIN_MUX!D35 -> SD1_CD | C36: =[1]PIN_MUX!L42 -> GPIO58 | D36: Func1 | E36: HiZ | F36: NA | G36: HiZ | H36: I | I36: HiZ | J36: I | K36: PU=0 | L36: PD=0
A37: =PIN_MUX!C36 -> U13 | B37: =PIN_MUX!D36 -> SD1_CMD_RSP | C37: =[1]PIN_MUX!L43 -> GPIO59 | D37: Func1 | E37: HiZ | F37: NA | G37: HiZ | H37: I | I37: HiZ | J37: I | K37: PU=0 | L37: PD=0
A38: =PIN_MUX!C37 -> U12 | B38: =PIN_MUX!D37 -> SD1_DATA_0 | C38: =[1]PIN_MUX!L44 -> GPIO60 | D38: Func1 | E38: HiZ | F38: NA | G38: HiZ | H38: I | I38: HiZ | J38: I | K38: PU=0 | L38: PD=0
... A41: =PIN_MUX!C40 -> U11 | B41: =PIN_MUX!D40 -> SD1_DATA_3 | C41: =[1]PIN_MUX!L47 -> GPIO63 | D41: Func1 | E41: HiZ | F41: NA | G41: HiZ | H41: I | I41: HiZ | J41: I | K41: PU=0 | L41: PD=0
A42: =PIN_MUX!C41 -> J3 | B42: =PIN_MUX!D41 -> GPIO0 | C42: =[1]PIN_MUX!K48 -> ARM_JTAG_TRSTN | D42: Func0 | E42: HiZ | F42: NA | G42: HiZ | H42: I | I42: HiZ | J42: I | K42: PU=0 | L42: PD=0
...

Sheet temp_file
A1: VSS | B1: W13
A2: DDR_ODT | B2: A2
A3: DDR_A14 | B3: A3
A4: nan | B4: Y18
A5: DDR_A1 | B5: A5
A6: DDR_BA1 | B6: A6
A7: DDR_CKE | B7: A8
A8: DDR_CLK_N | B8: A9
A9: DDR_DQ1 | B9: A11
A10: DDR_DQ4 | B10: A13
A11: DDR_DQS1_P | B11: A15
A12: DDR_DQS0_N | B12: A16
... A180: CKP_MIPI | B180: Y17
A182: DN0_MIPI | B182: 1
A183: DP0_MIPI | B183: 2
A184: DP1_MIPI | B184: 3
A185: DN1_MIPI | B185: 4
A186: CKN_MIPI | B186: 5
A187: CKP_MIPI | B187: 6
A188: REXT_MIPI | B188: 7
A189: SENSOR_RSTN | B189: 8
A190: SENSOR_CLK | B190: 9
A191: I2C0_SDA | B191: 10
A192: I2C0_SCL | B192: 11
A193: XAIN0_SADC | B193: 12
... A261: VDDA_RTC | B261: 44

Sheet 管脚列表BGA
B2: BGA
B3: Pin# | C3: Pin_Name | D3: Remark
B4: A1 | C4: VSS | D4: 地
B5: B1 | C5: DDR_CAL | D5: 外接240Ω电阻(±1%) （不能与DDR_ZQ共用）
B6: C1 | C6: DDR_ZQ | D6: 外接240Ω电阻(±1%) （不能与DDR_CAL共用）
B7: D1 | C7: RESETN | D7: 1.8V 信号
B8: E1 | C8: CLK_IN | D8: 1.8V 24M晶体输入。
B9: F1 | C9: NA | D9: NA
B10: G1 | C10: XIN_RTC | D10: RTC晶体输入。
B11: H1 | C11: NA | D11: NA
B12: J1 | C12: GPIO3 | D12: 3.3V 通用输入输出。
B13: K1 | C13: NA | D13: NA
B14: L1 | C14: I2C1_SDA | D14: 3.3V I2C总线1时钟。
... B363: Y18 | C363: NA | D363: NA

Sheet 更新记录
A1: 日期 | B1: 版本 | D1: 更新记录：
A2: 45012 | B2: 1 | D2: 新建pinout。
